Workbook

Sheet Start
A1: MyOrg · AI control self-assessment
A2: Enterprise Risk Management · AI Risk Series · Assess one AI use-case against the control expectations in ERM-ADV-AI-001 to 013
B4: STEP 1
B5: Use-case details
B7: Use-case name | E7: e.g. Client reporting drafting assistant
B8: Use-case owner | E8: Name and role
B9: Assessed risk tier
B10: Completed by
B11: Date of assessment
B13: STEP 2
B14: Scope
B15: These five answers decide which advisories apply. Where the answer is No, the related advisory is switched out of scope and excluded from every score.
B17: Scoping question | C17: Yes / No | D17: Gates | E17: What this covers
B18: Is any part of the AI capability supplied by, or embedded within, a third party? | C18: Yes | D18: ERM-ADV-AI-005 | E18: Includes foundation models, AI applications, and AI features switched on inside software the firm already licenses.
B19: Does the AI system access firm systems, repositories, or data beyond what the user provides in the request? | C19: No | D19: ERM-ADV-AI-006 | E19: Includes retrieval from document stores, database or API access, and mailbox or calendar access.
B20: Can the AI system take actions with effects outside itself, rather than only producing output for a person? | C20: No | D20: ERM-ADV-AI-007 | E20: Includes writing to systems, sending messages, calling tools, and triggering downstream processes.
B21: Does the AI system process content the firm does not control? | C21: No | D21: ERM-ADV-AI-008 | E21: Includes inbound email, uploaded documents from outside the firm, web pages, and third-party tool responses.
B22: Does the output reach clients, counterparties, candidates, or the public, or inform decisions about individuals? | C22: Yes | D22: ERM-ADV-AI-013 | E22: Also applies where the firm makes statements about this capability in marketing or due-diligence responses.
B24: HOW TO USE
B25: Legend and method
B26: Cells shaded pale blue are yours to complete. | C26: Everything else is a formula and is locked. To edit structure, use Review › Unprotect Sheet — no password is set.
B27: Work through the Assessment sheet. | C27: Choose one response per question from the dropdown in the Response column, then record how you know in the Evidence column.
B28: Scoring. | C28: In place = 2 points, Partially in place = 1, Not in place = 0. Not applicable is excluded from both the points earned and the points available.
B29: Overall score is question-weighted. | C29: Total points earned divided by total points available across all applicable questions — not an average of the thirteen advisory scores.
B30: Dashboard and Gap register update automatically. | C30: The Gap register lists every question answered Not in place or Partially in place, ready for owners and dates.
B31: Ratings. | C31: Not established below 40%, Developing 40–64%, Established 65–84%, Embedded 85% and above.
B33: EXAMPLE
B34: One completed row, for format
B35: Question | C35: Response | D35: Points | E35: Evidence / how you know
B36: 001.4 Are reviews logged, and is control degradation monitored? | C36: Partially in place | D36: 1 | E36: Reviewer and timestamp captured in the workflow tool; disposition is free text and not reportable. Rejection-rate trending not yet built. Owner: J. Patel, target 30 Sep.
B38: This workbook mirrors the HTML self-assessment (ERM-ADV-AI-SA-01). It is a first-line self-assessment producing a draft view of control maturity for one use-case — not a risk rating, a control effectiveness conclusion, or an approval. Second-line challenge and evidence testing sit outside it.
B40: VIEWS EXPRESSED ARE THE AUTHOR'S OWN AND DO NOT REPRESENT THOSE OF ANY EMPLOYER OR CLIENT. THIS IS A REFERENCE TEMPLATE, NOT FIRM POLICY, AND IS NOT INVESTMENT, LEGAL, OR COMPLIANCE ADVICE.

Sheet Assessment
A1: MyOrg · Assessment
A2: Choose one response per question. Pale blue cells are yours to complete; Points, and the Dashboard and Gap register sheets, calculate themselves.
A4: Ref | B4: ID | C4: Question | D4: What “In place” means | E4: Response | F4: Points | G4: Max | H4: Evidence / how you know | I4: Remediation owner | J4: Target date | K4: InScope | L4: GapRank
A5: ERM-ADV-AI-001 · Human in the loop — Whether human oversight cited as a control can actually achieve its objective.
A6: 001 | B6: 001.1 | C6: Is the reviewer a named role with the competence to judge the output independently? | D6: In place means the reviewing role is documented and could reasonably have produced or verified the work without the AI — not simply that someone signs off. | F6: =IF($K6=FALSE(),"",IF($E6="In place",2,IF($E6="Partially in place",1,IF($E6="Not in place",0,"")))) | G6: =IF($K6=FALSE(),"",IF(OR($E6="In place",$E6="Partially in place",$E6="Not in place"),2,"")) | K6: =TRUE() -> TRUE | L6: =IF(AND($K6=TRUE(),OR($E6="Not in place",$E6="Partially in place")),COUNTIFS($K$6:$K6,TRUE(),$E$6:$E6,"Not in place")+COUNTIFS($K$6:$K6,TRUE(),$E$6:$E6,"Partially in place"),"")
A7: 001 | B7: 001.2 | C7: Can the reviewer realistically review, and does the workflow stop the output until they have? | D7: In place means volume and time per item are quantified and defensible, and the output cannot proceed on a timeout or be bypassed. | F7: =IF($K7=FALSE(),"",IF($E7="In place",2,IF($E7="Partially in place",1,IF($E7="Not in place",0,"")))) | G7: =IF($K7=FALSE(),"",IF(OR($E7="In place",$E7="Partially in place",$E7="Not in place"),2,"")) | K7: =TRUE() -> TRUE | L7: =IF(AND($K7=TRUE(),OR($E7="Not in place",$E7="Partially in place")),COUNTIFS($K$6:$K7,TRUE(),$E$6:$E7,"Not in place")+COUNTIFS($K$6:$K7,TRUE(),$E$6:$E7,"Partially in place"),"")
A8: 001 | B8: 001.3 | C8: Are there documented review criteria and a defined escalation route? | D8: In place means the reviewer knows what wrong looks like for this use-case, and knows where to send what they cannot resolve. | F8: =IF($K8=FALSE(),"",IF($E8="In place",2,IF($E8="Partially in place",1,IF($E8="Not in place",0,"")))) | G8: =IF($K8=FALSE(),"",IF(OR($E8="In place",$E8="Partially in place",$E8="Not in place"),2,"")) | K8: =TRUE() -> TRUE | L8: =IF(AND($K8=TRUE(),OR($E8="Not in place",$E8="Partially in place")),COUNTIFS($K$6:$K8,TRUE(),$E$6:$E8,"Not in place")+COUNTIFS($K$6:$K8,TRUE(),$E$6:$E8,"Partially in place"),"")
A9: 001 | B9: 001.4 | C9: Are reviews logged, and is control degradation monitored? | D9: In place means reviewer, timestamp and disposition are recorded and testable, and indicators such as rejection rates trending to zero are actively watched. | F9: =IF($K9=FALSE(),"",IF($E9="In place",2,IF($E9="Partially in place",1,IF($E9="Not in place",0,"")))) | G9: =IF($K9=FALSE(),"",IF(OR($E9="In place",$E9="Partially in place",$E9="Not in place"),2,"")) | K9: =TRUE() -> TRUE | L9: =IF(AND($K9=TRUE(),OR($E9="Not in place",$E9="Partially in place")),COUNTIFS($K$6:$K9,TRUE(),$E$6:$E9,"Not in place")+COUNTIFS($K$6:$K9,TRUE(),$E$6:$E9,"Partially in place"),"")
A10: ERM-ADV-AI-002 · Intake and risk tiering — Whether the use-case is registered, tiered, and owned before it is relied upon.
A11: 002 | B11: 002.1 | C11: Is there a named use-case owner and accountable executive, with the affected process documented? | D11: In place means both are recorded in the inventory and the submission states what depends on the output being right. | F11: =IF($K11=FALSE(),"",IF($E11="In place",2,IF($E11="Partially in place",1,IF($E11="Not in place",0,"")))) | G11: =IF($K11=FALSE(),"",IF(OR($E11="In place",$E11="Partially in place",$E11="Not in place"),2,"")) | K11: =TRUE() -> TRUE | L11: =IF(AND($K11=TRUE(),OR($E11="Not in place",$E11="Partially in place")),COUNTIFS($K$6:$K11,TRUE(),$E$6:$E11,"Not in place")+COUNTIFS($K$6:$K11,TRUE(),$E$6:$E11,"Partially in place"),"")
A12: 002 | B12: 002.2 | C12: Are the data classifications of inputs and outputs recorded? | D12: In place means classifications are stated explicitly, including anything personal, client-identifying, or confidential. | F12: =IF($K12=FALSE(),"",IF($E12="In place",2,IF($E12="Partially in place",1,IF($E12="Not in place",0,"")))) | G12: =IF($K12=FALSE(),"",IF(OR($E12="In place",$E12="Partially in place",$E12="Not in place"),2,"")) | K12: =TRUE() -> TRUE | L12: =IF(AND($K12=TRUE(),OR($E12="Not in place",$E12="Partially in place")),COUNTIFS($K$6:$K12,TRUE(),$E$6:$E12,"Not in place")+COUNTIFS($K$6:$K12,TRUE(),$E$6:$E12,"Partially in place"),"")
A13: 002 | B13: 002.3 | C13: Has a risk tier been assigned against published criteria, with proportionate controls mapped? | D13: In place means the tier, the rationale, and the required control set are documented — and deviations explained. | F13: =IF($K13=FALSE(),"",IF($E13="In place",2,IF($E13="Partially in place",1,IF($E13="Not in place",0,"")))) | G13: =IF($K13=FALSE(),"",IF(OR($E13="In place",$E13="Partially in place",$E13="Not in place"),2,"")) | K13: =TRUE() -> TRUE | L13: =IF(AND($K13=TRUE(),OR($E13="Not in place",$E13="Partially in place")),COUNTIFS($K$6:$K13,TRUE(),$E$6:$E13,"Not in place")+COUNTIFS($K$6:$K13,TRUE(),$E$6:$E13,"Partially in place"),"")
A14: 002 | B14: 002.4 | C14: Was approval recorded before production use, and is the inventory entry re-attested? | D14: In place means dated approval precedes live use, and there is a re-attestation frequency and a decommissioning route. | F14: =IF($K14=FALSE(),"",IF($E14="In place",2,IF($E14="Partially in place",1,IF($E14="Not in place",0,"")))) | G14: =IF($K14=FALSE(),"",IF(OR($E14="In place",$E14="Partially in place",$E14="Not in place"),2,"")) | K14: =TRUE() -> TRUE | L14: =IF(AND($K14=TRUE(),OR($E14="Not in place",$E14="Partially in place")),COUNTIFS($K$6:$K14,TRUE(),$E$6:$E14,"Not in place")+COUNTIFS($K$6:$K14,TRUE(),$E$6:$E14,"Partially in place"),"")
A15: ERM-ADV-AI-003 · Data and input controls — Whether what is submitted to the AI system is controlled, minimised and traceable.
A16: 003 | B16: 003.1 | C16: Is the tool on the approved list for the data classifications this use-case handles? | D16: In place means an approval record exists that names the permitted classifications, not just the tool. | F16: =IF($K16=FALSE(),"",IF($E16="In place",2,IF($E16="Partially in place",1,IF($E16="Not in place",0,"")))) | G16: =IF($K16=FALSE(),"",IF(OR($E16="In place",$E16="Partially in place",$E16="Not in place"),2,"")) | K16: =TRUE() -> TRUE | L16: =IF(AND($K16=TRUE(),OR($E16="Not in place",$E16="Partially in place")),COUNTIFS($K$6:$K16,TRUE(),$E$6:$E16,"Not in place")+COUNTIFS($K$6:$K16,TRUE(),$E$6:$E16,"Partially in place"),"")
A17: 003 | B17: 003.2 | C17: Are retention, model-training and sub-processing terms confirmed in writing? | D17: In place means the firm has evidence of whether inputs are retained, used for training, or shared — not an inference from marketing material. | F17: =IF($K17=FALSE(),"",IF($E17="In place",2,IF($E17="Partially in place",1,IF($E17="Not in place",0,"")))) | G17: =IF($K17=FALSE(),"",IF(OR($E17="In place",$E17="Partially in place",$E17="Not in place"),2,"")) | K17: =TRUE() -> TRUE | L17: =IF(AND($K17=TRUE(),OR($E17="Not in place",$E17="Partially in place")),COUNTIFS($K$6:$K17,TRUE(),$E$6:$E17,"Not in place")+COUNTIFS($K$6:$K17,TRUE(),$E$6:$E17,"Partially in place"),"")
A18: 003 | B18: 003.3 | C18: Is at least one technical control enforcing this, alongside data minimisation? | D18: In place means tenancy isolation, egress or data-loss-prevention rules, or disabled provider-side training — plus removal or masking of data the outcome does not need. | F18: =IF($K18=FALSE(),"",IF($E18="In place",2,IF($E18="Partially in place",1,IF($E18="Not in place",0,"")))) | G18: =IF($K18=FALSE(),"",IF(OR($E18="In place",$E18="Partially in place",$E18="Not in place"),2,"")) | K18: =TRUE() -> TRUE | L18: =IF(AND($K18=TRUE(),OR($E18="Not in place",$E18="Partially in place")),COUNTIFS($K$6:$K18,TRUE(),$E$6:$E18,"Not in place")+COUNTIFS($K$6:$K18,TRUE(),$E$6:$E18,"Partially in place"),"")
A19: 003 | B19: 003.4 | C19: Does retrieval respect source-system entitlements, and have cross-border flows been assessed? | D19: In place means the system reads with the requesting user's permissions, source repositories were reviewed for over-sharing, and processing locations are documented. | F19: =IF($K19=FALSE(),"",IF($E19="In place",2,IF($E19="Partially in place",1,IF($E19="Not in place",0,"")))) | G19: =IF($K19=FALSE(),"",IF(OR($E19="In place",$E19="Partially in place",$E19="Not in place"),2,"")) | K19: =TRUE() -> TRUE | L19: =IF(AND($K19=TRUE(),OR($E19="Not in place",$E19="Partially in place")),COUNTIFS($K$6:$K19,TRUE(),$E$6:$E19,"Not in place")+COUNTIFS($K$6:$K19,TRUE(),$E$6:$E19,"Partially in place"),"")
A20: 003 | B20: 003.5 | C20: Can the firm establish what was submitted, without the log becoming an unprotected store? | D20: In place means input traceability exists proportionate to tier, and the log store is itself classified, access-controlled and retention-bound. | F20: =IF($K20=FALSE(),"",IF($E20="In place",2,IF($E20="Partially in place",1,IF($E20="Not in place",0,"")))) | G20: =IF($K20=FALSE(),"",IF(OR($E20="In place",$E20="Partially in place",$E20="Not in place"),2,"")) | K20: =TRUE() -> TRUE | L20: =IF(AND($K20=TRUE(),OR($E20="Not in place",$E20="Partially in place")),COUNTIFS($K$6:$K20,TRUE(),$E$6:$E20,"Not in place")+COUNTIFS($K$6:$K20,TRUE(),$E$6:$E20,"Partially in place"),"")
A21: ERM-ADV-AI-004 · Output reliability — Whether the correctness of AI output is defined, evidenced and monitored.
A22: 004 | B22: 004.1 | C22: Is there a defined accuracy standard and error tolerance for this use-case? | D22: In place means the submission states what correct output looks like and which categories of error matter most. | F22: =IF($K22=FALSE(),"",IF($E22="In place",2,IF($E22="Partially in place",1,IF($E22="Not in place",0,"")))) | G22: =IF($K22=FALSE(),"",IF(OR($E22="In place",$E22="Partially in place",$E22="Not in place"),2,"")) | K22: =TRUE() -> TRUE | L22: =IF(AND($K22=TRUE(),OR($E22="Not in place",$E22="Partially in place")),COUNTIFS($K$6:$K22,TRUE(),$E$6:$E22,"Not in place")+COUNTIFS($K$6:$K22,TRUE(),$E$6:$E22,"Partially in place"),"")
A23: 004 | B23: 004.2 | C23: Is factual output grounded in governed sources with attribution a reviewer can follow? | D23: In place means retrieval from identified, current sources with citations that resolve — not instruction to the model not to invent content. | F23: =IF($K23=FALSE(),"",IF($E23="In place",2,IF($E23="Partially in place",1,IF($E23="Not in place",0,"")))) | G23: =IF($K23=FALSE(),"",IF(OR($E23="In place",$E23="Partially in place",$E23="Not in place"),2,"")) | K23: =TRUE() -> TRUE | L23: =IF(AND($K23=TRUE(),OR($E23="Not in place",$E23="Partially in place")),COUNTIFS($K$6:$K23,TRUE(),$E$6:$E23,"Not in place")+COUNTIFS($K$6:$K23,TRUE(),$E$6:$E23,"Partially in place"),"")
A24: 004 | B24: 004.3 | C24: Was the system evaluated against a retained test set before production, to a pre-set threshold? | D24: In place means documented results against representative and edge cases, with the pass threshold defined in advance. | F24: =IF($K24=FALSE(),"",IF($E24="In place",2,IF($E24="Partially in place",1,IF($E24="Not in place",0,"")))) | G24: =IF($K24=FALSE(),"",IF(OR($E24="In place",$E24="Partially in place",$E24="Not in place"),2,"")) | K24: =TRUE() -> TRUE | L24: =IF(AND($K24=TRUE(),OR($E24="Not in place",$E24="Partially in place")),COUNTIFS($K$6:$K24,TRUE(),$E$6:$E24,"Not in place")+COUNTIFS($K$6:$K24,TRUE(),$E$6:$E24,"Partially in place"),"")
A25: 004 | B25: 004.4 | C25: Are there automated guardrails and ongoing quality sampling in production? | D25: In place means scope, format or reconciliation checks in the system, plus a defined sample checked by someone competent to judge it, with results trended. | F25: =IF($K25=FALSE(),"",IF($E25="In place",2,IF($E25="Partially in place",1,IF($E25="Not in place",0,"")))) | G25: =IF($K25=FALSE(),"",IF(OR($E25="In place",$E25="Partially in place",$E25="Not in place"),2,"")) | K25: =TRUE() -> TRUE | L25: =IF(AND($K25=TRUE(),OR($E25="Not in place",$E25="Partially in place")),COUNTIFS($K$6:$K25,TRUE(),$E$6:$E25,"Not in place")+COUNTIFS($K$6:$K25,TRUE(),$E$6:$E25,"Partially in place"),"")
A26: 004 | B26: 004.5 | C26: Are known limitations communicated to users, and is the system re-evaluated on change? | D26: In place means users know what it is unreliable for, and evaluation repeats when the model, prompt, sources or scope change. | F26: =IF($K26=FALSE(),"",IF($E26="In place",2,IF($E26="Partially in place",1,IF($E26="Not in place",0,"")))) | G26: =IF($K26=FALSE(),"",IF(OR($E26="In place",$E26="Partially in place",$E26="Not in place"),2,"")) | K26: =TRUE() -> TRUE | L26: =IF(AND($K26=TRUE(),OR($E26="Not in place",$E26="Partially in place")),COUNTIFS($K$6:$K26,TRUE(),$E$6:$E26,"Not in place")+COUNTIFS($K$6:$K26,TRUE(),$E$6:$E26,"Partially in place"),"")
A27: ="ERM-ADV-AI-005 · Third-party and embedded AI — Whether supplied AI capability is diligenced, contracted for, and survivable if withdrawn."&IF(Start!$C$18="Yes",""," ··· OUT OF SCOPE — excluded from scoring") -> ERM-ADV-AI-005 · Third-party and embedded AI — Whether supplied AI capability is diligenced, contracted for, and survivable if withdrawn.
A28: 005 | B28: 005.1 | C28: Is the supplier AI capability identified and registered, including features enabled by default? | D28: In place means suppliers have been asked directly where their products use AI, and the answer is reflected in the inventory. | F28: =IF($K28=FALSE(),"",IF($E28="In place",2,IF($E28="Partially in place",1,IF($E28="Not in place",0,"")))) | G28: =IF($K28=FALSE(),"",IF(OR($E28="In place",$E28="Partially in place",$E28="Not in place"),2,"")) | K28: =Start!$C$18="Yes" -> TRUE | L28: =IF(AND($K28=TRUE(),OR($E28="Not in place",$E28="Partially in place")),COUNTIFS($K$6:$K28,TRUE(),$E$6:$E28,"Not in place")+COUNTIFS($K$6:$K28,TRUE(),$E$6:$E28,"Partially in place"),"")
A29: 005 | B29: 005.2 | C29: Are model provenance, processing locations and sub-processors known, with security and privacy assessments complete? | D29: In place means the firm knows what sits behind the feature, or has explicitly accepted not knowing at a documented tier. | F29: =IF($K29=FALSE(),"",IF($E29="In place",2,IF($E29="Partially in place",1,IF($E29="Not in place",0,"")))) | G29: =IF($K29=FALSE(),"",IF(OR($E29="In place",$E29="Partially in place",$E29="Not in place"),2,"")) | K29: =Start!$C$18="Yes" -> TRUE | L29: =IF(AND($K29=TRUE(),OR($E29="Not in place",$E29="Partially in place")),COUNTIFS($K$6:$K29,TRUE(),$E$6:$E29,"Not in place")+COUNTIFS($K$6:$K29,TRUE(),$E$6:$E29,"Partially in place"),"")
A30: 005 | B30: 005.3 | C30: Do contract terms cover training use, deletion, security, incident notification, IP indemnity and audit rights? | D30: In place means the protections exist in the agreement, or a deviation has been accepted and recorded. | F30: =IF($K30=FALSE(),"",IF($E30="In place",2,IF($E30="Partially in place",1,IF($E30="Not in place",0,"")))) | G30: =IF($K30=FALSE(),"",IF(OR($E30="In place",$E30="Partially in place",$E30="Not in place"),2,"")) | K30: =Start!$C$18="Yes" -> TRUE | L30: =IF(AND($K30=TRUE(),OR($E30="Not in place",$E30="Partially in place")),COUNTIFS($K$6:$K30,TRUE(),$E$6:$E30,"Not in place")+COUNTIFS($K$6:$K30,TRUE(),$E$6:$E30,"Partially in place"),"")
A31: 005 | B31: 005.4 | C31: Does the firm hold its own evidence that the capability performs adequately for this use? | D31: In place means evaluation, pilot results or reference testing — not reliance on supplier claims alone. | F31: =IF($K31=FALSE(),"",IF($E31="In place",2,IF($E31="Partially in place",1,IF($E31="Not in place",0,"")))) | G31: =IF($K31=FALSE(),"",IF(OR($E31="In place",$E31="Partially in place",$E31="Not in place"),2,"")) | K31: =Start!$C$18="Yes" -> TRUE | L31: =IF(AND($K31=TRUE(),OR($E31="Not in place",$E31="Partially in place")),COUNTIFS($K$6:$K31,TRUE(),$E$6:$E31,"Not in place")+COUNTIFS($K$6:$K31,TRUE(),$E$6:$E31,"Partially in place"),"")
A32: 005 | B32: 005.5 | C32: Are change notification rights in place, and is there a credible fallback if the capability is withdrawn? | D32: In place means a named owner receives change notices within a defined window, and the fallback has been confirmed as viable rather than asserted. | F32: =IF($K32=FALSE(),"",IF($E32="In place",2,IF($E32="Partially in place",1,IF($E32="Not in place",0,"")))) | G32: =IF($K32=FALSE(),"",IF(OR($E32="In place",$E32="Partially in place",$E32="Not in place"),2,"")) | K32: =Start!$C$18="Yes" -> TRUE | L32: =IF(AND($K32=TRUE(),OR($E32="Not in place",$E32="Partially in place")),COUNTIFS($K$6:$K32,TRUE(),$E$6:$E32,"Not in place")+COUNTIFS($K$6:$K32,TRUE(),$E$6:$E32,"Partially in place"),"")
A33: ="ERM-ADV-AI-006 · Agent identity and access — Whether AI access to firm systems is attributable, least-privilege and revocable."&IF(Start!$C$19="Yes",""," ··· OUT OF SCOPE — excluded from scoring") -> ERM-ADV-AI-006 · Agent identity and access — Whether AI access to firm systems is attributable, least-privilege and revocable. ··· OUT OF SCOPE — excluded from scoring
A34: 006 | B34: 006.1 | C34: Does the AI operate under a distinct non-human identity with a named human owner? | D34: In place means it is distinguishable in logs from human users and other agents, and is not a shared service account. | F34: =IF($K34=FALSE(),"",IF($E34="In place",2,IF($E34="Partially in place",1,IF($E34="Not in place",0,"")))) | G34: =IF($K34=FALSE(),"",IF(OR($E34="In place",$E34="Partially in place",$E34="Not in place"),2,"")) | K34: =Start!$C$19="Yes" -> FALSE | L34: =IF(AND($K34=TRUE(),OR($E34="Not in place",$E34="Partially in place")),COUNTIFS($K$6:$K34,TRUE(),$E$6:$E34,"Not in place")+COUNTIFS($K$6:$K34,TRUE(),$E$6:$E34,"Partially in place"),"")
A35: 006 | B35: 006.2 | C35: Are entitlements least-privilege, justified against the use-case, and bounded when acting for a user? | D35: In place means every entitlement traces to a use-case requirement, and the system cannot reach what the requesting user could not reach. | F35: =IF($K35=FALSE(),"",IF($E35="In place",2,IF($E35="Partially in place",1,IF($E35="Not in place",0,"")))) | G35: =IF($K35=FALSE(),"",IF(OR($E35="In place",$E35="Partially in place",$E35="Not in place"),2,"")) | K35: =Start!$C$19="Yes" -> FALSE | L35: =IF(AND($K35=TRUE(),OR($E35="Not in place",$E35="Partially in place")),COUNTIFS($K$6:$K35,TRUE(),$E$6:$E35,"Not in place")+COUNTIFS($K$6:$K35,TRUE(),$E$6:$E35,"Partially in place"),"")
A36: 006 | B36: 006.3 | C36: Are credentials held in an approved vault, scoped and rotated? | D36: In place means no secrets in prompts, configuration files, code repositories or logs. | F36: =IF($K36=FALSE(),"",IF($E36="In place",2,IF($E36="Partially in place",1,IF($E36="Not in place",0,"")))) | G36: =IF($K36=FALSE(),"",IF(OR($E36="In place",$E36="Partially in place",$E36="Not in place"),2,"")) | K36: =Start!$C$19="Yes" -> FALSE | L36: =IF(AND($K36=TRUE(),OR($E36="Not in place",$E36="Partially in place")),COUNTIFS($K$6:$K36,TRUE(),$E$6:$E36,"Not in place")+COUNTIFS($K$6:$K36,TRUE(),$E$6:$E36,"Partially in place"),"")
A37: 006 | B37: 006.4 | C37: Are entitlements recertified, and has revocation been tested? | D37: In place means review at least as often as comparable human privileged access, and a tested method to disable the identity and stop in-flight activity. | F37: =IF($K37=FALSE(),"",IF($E37="In place",2,IF($E37="Partially in place",1,IF($E37="Not in place",0,"")))) | G37: =IF($K37=FALSE(),"",IF(OR($E37="In place",$E37="Partially in place",$E37="Not in place"),2,"")) | K37: =Start!$C$19="Yes" -> FALSE | L37: =IF(AND($K37=TRUE(),OR($E37="Not in place",$E37="Partially in place")),COUNTIFS($K$6:$K37,TRUE(),$E$6:$E37,"Not in place")+COUNTIFS($K$6:$K37,TRUE(),$E$6:$E37,"Partially in place"),"")
A38: ="ERM-ADV-AI-007 · Autonomy and action boundaries — Whether what the AI may do is defined in advance and enforced by the system."&IF(Start!$C$20="Yes",""," ··· OUT OF SCOPE — excluded from scoring") -> ERM-ADV-AI-007 · Autonomy and action boundaries — Whether what the AI may do is defined in advance and enforced by the system. ··· OUT OF SCOPE — excluded from scoring
A39: 007 | B39: 007.1 | C39: Are permitted actions and tools an enumerated allow-list, with everything else denied? | D39: In place means adding a tool is a change requiring assessment, not a configuration convenience. | F39: =IF($K39=FALSE(),"",IF($E39="In place",2,IF($E39="Partially in place",1,IF($E39="Not in place",0,"")))) | G39: =IF($K39=FALSE(),"",IF(OR($E39="In place",$E39="Partially in place",$E39="Not in place"),2,"")) | K39: =Start!$C$20="Yes" -> FALSE | L39: =IF(AND($K39=TRUE(),OR($E39="Not in place",$E39="Partially in place")),COUNTIFS($K$6:$K39,TRUE(),$E$6:$E39,"Not in place")+COUNTIFS($K$6:$K39,TRUE(),$E$6:$E39,"Partially in place"),"")
A40: 007 | B40: 007.2 | C40: Do material or irreversible actions require explicit human authorisation, within enforced quantitative limits? | D40: In place means authorisation cannot be satisfied by a timeout, and value, volume, rate and time-window limits halt rather than log on breach. | F40: =IF($K40=FALSE(),"",IF($E40="In place",2,IF($E40="Partially in place",1,IF($E40="Not in place",0,"")))) | G40: =IF($K40=FALSE(),"",IF(OR($E40="In place",$E40="Partially in place",$E40="Not in place"),2,"")) | K40: =Start!$C$20="Yes" -> FALSE | L40: =IF(AND($K40=TRUE(),OR($E40="Not in place",$E40="Partially in place")),COUNTIFS($K$6:$K40,TRUE(),$E$6:$E40,"Not in place")+COUNTIFS($K$6:$K40,TRUE(),$E$6:$E40,"Partially in place"),"")
A41: 007 | B41: 007.3 | C41: Are the boundaries enforced outside the model, rather than by instruction? | D41: In place means permissions, gateways, policy enforcement or validation layers refuse the action — the prompt is not the control. | F41: =IF($K41=FALSE(),"",IF($E41="In place",2,IF($E41="Partially in place",1,IF($E41="Not in place",0,"")))) | G41: =IF($K41=FALSE(),"",IF(OR($E41="In place",$E41="Partially in place",$E41="Not in place"),2,"")) | K41: =Start!$C$20="Yes" -> FALSE | L41: =IF(AND($K41=TRUE(),OR($E41="Not in place",$E41="Partially in place")),COUNTIFS($K$6:$K41,TRUE(),$E$6:$E41,"Not in place")+COUNTIFS($K$6:$K41,TRUE(),$E$6:$E41,"Partially in place"),"")
...

Sheet Dashboard
A1: MyOrg · Dashboard
B3: Use-case | C3: =Start!C7 -> 0 | E3: OVERALL SCORE | G3: RATING
B4: Owner | C4: =Start!C8 -> 0 | E4: =IF(SUM($H$16:$H$28)=0,"",SUM($G$16:$G$28)/SUM($H$16:$H$28)) | G4: =IF($E$4="","Not started",IF($E$4>=0.85,"Embedded",IF($E$4>=0.65,"Established",IF($E$4>=0.4,"Developing","Not established")))) -> Not started
B5: Tier | C5: =Start!C9 -> 0
B6: Completed by | C6: =Start!C10 -> 0 | E6: GAPS OPEN | G6: PROGRESS
E7: =MAX(Assessment!$L:$L) -> 0 | G7: =SUM($E$16:$E$28)&" of "&SUM($F$16:$F$28)&" applicable questions answered" -> 0 of 48 applicable questions answered
B15: Ref | C15: Control area | D15: In scope | E15: Answered | F15: Questions | G15: Points | H15: Available | I15: Score | J15: Rating
B16: 001 | C16: Human in the loop | D16: Yes | E16: =IF($D16="No",0,COUNTIFS(Assessment!$A:$A,$B16,Assessment!$E:$E,"<>")) -> 0 | F16: =IF($D16="No",0,COUNTIFS(Assessment!$A:$A,$B16)) -> 4 | G16: =SUMIFS(Assessment!$F:$F,Assessment!$A:$A,$B16) -> 0 | H16: =SUMIFS(Assessment!$G:$G,Assessment!$A:$A,$B16) -> 0 | I16: =IF($H16=0,"",$G16/$H16) | J16: =IF($D16="No","Out of scope",IF($I16="","Not scored",IF($I16>=0.85,"Embedded",IF($I16>=0.65,"Established",IF($I16>=0.4,"Developing","Not established"))))) -> Not scored
B17: 002 | C17: Intake and risk tiering | D17: Yes | E17: =IF($D17="No",0,COUNTIFS(Assessment!$A:$A,$B17,Assessment!$E:$E,"<>")) -> 0 | F17: =IF($D17="No",0,COUNTIFS(Assessment!$A:$A,$B17)) -> 4 | G17: =SUMIFS(Assessment!$F:$F,Assessment!$A:$A,$B17) -> 0 | H17: =SUMIFS(Assessment!$G:$G,Assessment!$A:$A,$B17) -> 0 | I17: =IF($H17=0,"",$G17/$H17) | J17: =IF($D17="No","Out of scope",IF($I17="","Not scored",IF($I17>=0.85,"Embedded",IF($I17>=0.65,"Established",IF($I17>=0.4,"Developing","Not established"))))) -> Not scored
B18: 003 | C18: Data and input controls | D18: Yes | E18: =IF($D18="No",0,COUNTIFS(Assessment!$A:$A,$B18,Assessment!$E:$E,"<>")) -> 0 | F18: =IF($D18="No",0,COUNTIFS(Assessment!$A:$A,$B18)) -> 5 | G18: =SUMIFS(Assessment!$F:$F,Assessment!$A:$A,$B18) -> 0 | H18: =SUMIFS(Assessment!$G:$G,Assessment!$A:$A,$B18) -> 0 | I18: =IF($H18=0,"",$G18/$H18) | J18: =IF($D18="No","Out of scope",IF($I18="","Not scored",IF($I18>=0.85,"Embedded",IF($I18>=0.65,"Established",IF($I18>=0.4,"Developing","Not established"))))) -> Not scored
B19: 004 | C19: Output reliability | D19: Yes | E19: =IF($D19="No",0,COUNTIFS(Assessment!$A:$A,$B19,Assessment!$E:$E,"<>")) -> 0 | F19: =IF($D19="No",0,COUNTIFS(Assessment!$A:$A,$B19)) -> 5 | G19: =SUMIFS(Assessment!$F:$F,Assessment!$A:$A,$B19) -> 0 | H19: =SUMIFS(Assessment!$G:$G,Assessment!$A:$A,$B19) -> 0 | I19: =IF($H19=0,"",$G19/$H19) | J19: =IF($D19="No","Out of scope",IF($I19="","Not scored",IF($I19>=0.85,"Embedded",IF($I19>=0.65,"Established",IF($I19>=0.4,"Developing","Not established"))))) -> Not scored
B20: 005 | C20: Third-party and embedded AI | D20: =IF(Start!$C$18="Yes","Yes","No") -> Yes | E20: =IF($D20="No",0,COUNTIFS(Assessment!$A:$A,$B20,Assessment!$E:$E,"<>")) -> 0 | F20: =IF($D20="No",0,COUNTIFS(Assessment!$A:$A,$B20)) -> 5 | G20: =SUMIFS(Assessment!$F:$F,Assessment!$A:$A,$B20) -> 0 | H20: =SUMIFS(Assessment!$G:$G,Assessment!$A:$A,$B20) -> 0 | I20: =IF($H20=0,"",$G20/$H20) | J20: =IF($D20="No","Out of scope",IF($I20="","Not scored",IF($I20>=0.85,"Embedded",IF($I20>=0.65,"Established",IF($I20>=0.4,"Developing","Not established"))))) -> Not scored
B21: 006 | C21: Agent identity and access | D21: =IF(Start!$C$19="Yes","Yes","No") -> No | E21: =IF($D21="No",0,COUNTIFS(Assessment!$A:$A,$B21,Assessment!$E:$E,"<>")) -> 0 | F21: =IF($D21="No",0,COUNTIFS(Assessment!$A:$A,$B21)) -> 0 | G21: =SUMIFS(Assessment!$F:$F,Assessment!$A:$A,$B21) -> 0 | H21: =SUMIFS(Assessment!$G:$G,Assessment!$A:$A,$B21) -> 0 | I21: =IF($H21=0,"",$G21/$H21) | J21: =IF($D21="No","Out of scope",IF($I21="","Not scored",IF($I21>=0.85,"Embedded",IF($I21>=0.65,"Established",IF($I21>=0.4,"Developing","Not established"))))) -> Out of scope
B22: 007 | C22: Autonomy and action boundaries | D22: =IF(Start!$C$20="Yes","Yes","No") -> No | E22: =IF($D22="No",0,COUNTIFS(Assessment!$A:$A,$B22,Assessment!$E:$E,"<>")) -> 0 | F22: =IF($D22="No",0,COUNTIFS(Assessment!$A:$A,$B22)) -> 0 | G22: =SUMIFS(Assessment!$F:$F,Assessment!$A:$A,$B22) -> 0 | H22: =SUMIFS(Assessment!$G:$G,Assessment!$A:$A,$B22) -> 0 | I22: =IF($H22=0,"",$G22/$H22) | J22: =IF($D22="No","Out of scope",IF($I22="","Not scored",IF($I22>=0.85,"Embedded",IF($I22>=0.65,"Established",IF($I22>=0.4,"Developing","Not established"))))) -> Out of scope
B23: 008 | C23: Prompt injection and untrusted content | D23: =IF(Start!$C$21="Yes","Yes","No") -> No | E23: =IF($D23="No",0,COUNTIFS(Assessment!$A:$A,$B23,Assessment!$E:$E,"<>")) -> 0 | F23: =IF($D23="No",0,COUNTIFS(Assessment!$A:$A,$B23)) -> 0 | G23: =SUMIFS(Assessment!$F:$F,Assessment!$A:$A,$B23) -> 0 | H23: =SUMIFS(Assessment!$G:$G,Assessment!$A:$A,$B23) -> 0 | I23: =IF($H23=0,"",$G23/$H23) | J23: =IF($D23="No","Out of scope",IF($I23="","Not scored",IF($I23>=0.85,"Embedded",IF($I23>=0.65,"Established",IF($I23>=0.4,"Developing","Not established"))))) -> Out of scope
B24: 009 | C24: Logging and records | D24: Yes | E24: =IF($D24="No",0,COUNTIFS(Assessment!$A:$A,$B24,Assessment!$E:$E,"<>")) -> 0 | F24: =IF($D24="No",0,COUNTIFS(Assessment!$A:$A,$B24)) -> 5 | G24: =SUMIFS(Assessment!$F:$F,Assessment!$A:$A,$B24) -> 0 | H24: =SUMIFS(Assessment!$G:$G,Assessment!$A:$A,$B24) -> 0 | I24: =IF($H24=0,"",$G24/$H24) | J24: =IF($D24="No","Out of scope",IF($I24="","Not scored",IF($I24>=0.85,"Embedded",IF($I24>=0.65,"Established",IF($I24>=0.4,"Developing","Not established"))))) -> Not scored
B25: 010 | C25: Change control | D25: Yes | E25: =IF($D25="No",0,COUNTIFS(Assessment!$A:$A,$B25,Assessment!$E:$E,"<>")) -> 0 | F25: =IF($D25="No",0,COUNTIFS(Assessment!$A:$A,$B25)) -> 5 | G25: =SUMIFS(Assessment!$F:$F,Assessment!$A:$A,$B25) -> 0 | H25: =SUMIFS(Assessment!$G:$G,Assessment!$A:$A,$B25) -> 0 | I25: =IF($H25=0,"",$G25/$H25) | J25: =IF($D25="No","Out of scope",IF($I25="","Not scored",IF($I25>=0.85,"Embedded",IF($I25>=0.65,"Established",IF($I25>=0.4,"Developing","Not established"))))) -> Not scored
B26: 011 | C26: Monitoring and effectiveness | D26: Yes | E26: =IF($D26="No",0,COUNTIFS(Assessment!$A:$A,$B26,Assessment!$E:$E,"<>")) -> 0 | F26: =IF($D26="No",0,COUNTIFS(Assessment!$A:$A,$B26)) -> 5 | G26: =SUMIFS(Assessment!$F:$F,Assessment!$A:$A,$B26) -> 0 | H26: =SUMIFS(Assessment!$G:$G,Assessment!$A:$A,$B26) -> 0 | I26: =IF($H26=0,"",$G26/$H26) | J26: =IF($D26="No","Out of scope",IF($I26="","Not scored",IF($I26>=0.85,"Embedded",IF($I26>=0.65,"Established",IF($I26>=0.4,"Developing","Not established"))))) -> Not scored
B27: 012 | C27: Acceptable use and competency | D27: Yes | E27: =IF($D27="No",0,COUNTIFS(Assessment!$A:$A,$B27,Assessment!$E:$E,"<>")) -> 0 | F27: =IF($D27="No",0,COUNTIFS(Assessment!$A:$A,$B27)) -> 5 | G27: =SUMIFS(Assessment!$F:$F,Assessment!$A:$A,$B27) -> 0 | H27: =SUMIFS(Assessment!$G:$G,Assessment!$A:$A,$B27) -> 0 | I27: =IF($H27=0,"",$G27/$H27) | J27: =IF($D27="No","Out of scope",IF($I27="","Not scored",IF($I27>=0.85,"Embedded",IF($I27>=0.65,"Established",IF($I27>=0.4,"Developing","Not established"))))) -> Not scored
B28: 013 | C28: Disclosure and transparency | D28: =IF(Start!$C$22="Yes","Yes","No") -> Yes | E28: =IF($D28="No",0,COUNTIFS(Assessment!$A:$A,$B28,Assessment!$E:$E,"<>")) -> 0 | F28: =IF($D28="No",0,COUNTIFS(Assessment!$A:$A,$B28)) -> 5 | G28: =SUMIFS(Assessment!$F:$F,Assessment!$A:$A,$B28) -> 0 | H28: =SUMIFS(Assessment!$G:$G,Assessment!$A:$A,$B28) -> 0 | I28: =IF($H28=0,"",$G28/$H28) | J28: =IF($D28="No","Out of scope",IF($I28="","Not scored",IF($I28>=0.85,"Embedded",IF($I28>=0.65,"Established",IF($I28>=0.4,"Developing","Not established"))))) -> Not scored
C29: All applicable control areas | E29: =SUM($E$16:$E$28) -> 0 | F29: =SUM($F$16:$F$28) -> 48 | G29: =SUM($G$16:$G$28) -> 0 | H29: =SUM($H$16:$H$28) -> 0 | I29: =IF($H29=0,"",$G29/$H29) | J29: =$G$4 -> Not started
B30: Source: responses recorded on the Assessment sheet. Overall score is question-weighted — total points earned divided by total points available across all applicable questions.

Sheet Gap register
A1: MyOrg · Gap register
A2: Every applicable question answered Not in place or Partially in place, in advisory order. This sheet is generated — edit the Assessment sheet, not this one.
A4: Ref | B4: ID | C4: Response | D4: Question | E4: What “In place” means | F4: Evidence / how you know | G4: Remediation owner | H4: Target date | I4: idx
A5: =IF($I5="","",IF(INDEX(Assessment!$A:$A,$I5)="","",INDEX(Assessment!$A:$A,$I5))) | B5: =IF($I5="","",IF(INDEX(Assessment!$B:$B,$I5)="","",INDEX(Assessment!$B:$B,$I5))) | C5: =IF($I5="","",IF(INDEX(Assessment!$E:$E,$I5)="","",INDEX(Assessment!$E:$E,$I5))) | D5: =IF($I5="","",IF(INDEX(Assessment!$C:$C,$I5)="","",INDEX(Assessment!$C:$C,$I5))) | E5: =IF($I5="","",IF(INDEX(Assessment!$D:$D,$I5)="","",INDEX(Assessment!$D:$D,$I5))) | F5: =IF($I5="","",IF(INDEX(Assessment!$H:$H,$I5)="","",INDEX(Assessment!$H:$H,$I5))) | G5: =IF($I5="","",IF(INDEX(Assessment!$I:$I,$I5)="","",INDEX(Assessment!$I:$I,$I5))) | H5: =IF($I5="","",IF(INDEX(Assessment!$J:$J,$I5)="","",INDEX(Assessment!$J:$J,$I5))) | I5: =IFERROR(MATCH(ROW()-4,Assessment!$L:$L,0),"")
A6: =IF($I6="","",IF(INDEX(Assessment!$A:$A,$I6)="","",INDEX(Assessment!$A:$A,$I6))) | B6: =IF($I6="","",IF(INDEX(Assessment!$B:$B,$I6)="","",INDEX(Assessment!$B:$B,$I6))) | C6: =IF($I6="","",IF(INDEX(Assessment!$E:$E,$I6)="","",INDEX(Assessment!$E:$E,$I6))) | D6: =IF($I6="","",IF(INDEX(Assessment!$C:$C,$I6)="","",INDEX(Assessment!$C:$C,$I6))) | E6: =IF($I6="","",IF(INDEX(Assessment!$D:$D,$I6)="","",INDEX(Assessment!$D:$D,$I6))) | F6: =IF($I6="","",IF(INDEX(Assessment!$H:$H,$I6)="","",INDEX(Assessment!$H:$H,$I6))) | G6: =IF($I6="","",IF(INDEX(Assessment!$I:$I,$I6)="","",INDEX(Assessment!$I:$I,$I6))) | H6: =IF($I6="","",IF(INDEX(Assessment!$J:$J,$I6)="","",INDEX(Assessment!$J:$J,$I6))) | I6: =IFERROR(MATCH(ROW()-4,Assessment!$L:$L,0),"")
A7: =IF($I7="","",IF(INDEX(Assessment!$A:$A,$I7)="","",INDEX(Assessment!$A:$A,$I7))) | B7: =IF($I7="","",IF(INDEX(Assessment!$B:$B,$I7)="","",INDEX(Assessment!$B:$B,$I7))) | C7: =IF($I7="","",IF(INDEX(Assessment!$E:$E,$I7)="","",INDEX(Assessment!$E:$E,$I7))) | D7: =IF($I7="","",IF(INDEX(Assessment!$C:$C,$I7)="","",INDEX(Assessment!$C:$C,$I7))) | E7: =IF($I7="","",IF(INDEX(Assessment!$D:$D,$I7)="","",INDEX(Assessment!$D:$D,$I7))) | F7: =IF($I7="","",IF(INDEX(Assessment!$H:$H,$I7)="","",INDEX(Assessment!$H:$H,$I7))) | G7: =IF($I7="","",IF(INDEX(Assessment!$I:$I,$I7)="","",INDEX(Assessment!$I:$I,$I7))) | H7: =IF($I7="","",IF(INDEX(Assessment!$J:$J,$I7)="","",INDEX(Assessment!$J:$J,$I7))) | I7: =IFERROR(MATCH(ROW()-4,Assessment!$L:$L,0),"")
A8: =IF($I8="","",IF(INDEX(Assessment!$A:$A,$I8)="","",INDEX(Assessment!$A:$A,$I8))) | B8: =IF($I8="","",IF(INDEX(Assessment!$B:$B,$I8)="","",INDEX(Assessment!$B:$B,$I8))) | C8: =IF($I8="","",IF(INDEX(Assessment!$E:$E,$I8)="","",INDEX(Assessment!$E:$E,$I8))) | D8: =IF($I8="","",IF(INDEX(Assessment!$C:$C,$I8)="","",INDEX(Assessment!$C:$C,$I8))) | E8: =IF($I8="","",IF(INDEX(Assessment!$D:$D,$I8)="","",INDEX(Assessment!$D:$D,$I8))) | F8: =IF($I8="","",IF(INDEX(Assessment!$H:$H,$I8)="","",INDEX(Assessment!$H:$H,$I8))) | G8: =IF($I8="","",IF(INDEX(Assessment!$I:$I,$I8)="","",INDEX(Assessment!$I:$I,$I8))) | H8: =IF($I8="","",IF(INDEX(Assessment!$J:$J,$I8)="","",INDEX(Assessment!$J:$J,$I8))) | I8: =IFERROR(MATCH(ROW()-4,Assessment!$L:$L,0),"")
A9: =IF($I9="","",IF(INDEX(Assessment!$A:$A,$I9)="","",INDEX(Assessment!$A:$A,$I9))) | B9: =IF($I9="","",IF(INDEX(Assessment!$B:$B,$I9)="","",INDEX(Assessment!$B:$B,$I9))) | C9: =IF($I9="","",IF(INDEX(Assessment!$E:$E,$I9)="","",INDEX(Assessment!$E:$E,$I9))) | D9: =IF($I9="","",IF(INDEX(Assessment!$C:$C,$I9)="","",INDEX(Assessment!$C:$C,$I9))) | E9: =IF($I9="","",IF(INDEX(Assessment!$D:$D,$I9)="","",INDEX(Assessment!$D:$D,$I9))) | F9: =IF($I9="","",IF(INDEX(Assessment!$H:$H,$I9)="","",INDEX(Assessment!$H:$H,$I9))) | G9: =IF($I9="","",IF(INDEX(Assessment!$I:$I,$I9)="","",INDEX(Assessment!$I:$I,$I9))) | H9: =IF($I9="","",IF(INDEX(Assessment!$J:$J,$I9)="","",INDEX(Assessment!$J:$J,$I9))) | I9: =IFERROR(MATCH(ROW()-4,Assessment!$L:$L,0),"")
A10: =IF($I10="","",IF(INDEX(Assessment!$A:$A,$I10)="","",INDEX(Assessment!$A:$A,$I10))) | B10: =IF($I10="","",IF(INDEX(Assessment!$B:$B,$I10)="","",INDEX(Assessment!$B:$B,$I10))) | C10: =IF($I10="","",IF(INDEX(Assessment!$E:$E,$I10)="","",INDEX(Assessment!$E:$E,$I10))) | D10: =IF($I10="","",IF(INDEX(Assessment!$C:$C,$I10)="","",INDEX(Assessment!$C:$C,$I10))) | E10: =IF($I10="","",IF(INDEX(Assessment!$D:$D,$I10)="","",INDEX(Assessment!$D:$D,$I10))) | F10: =IF($I10="","",IF(INDEX(Assessment!$H:$H,$I10)="","",INDEX(Assessment!$H:$H,$I10))) | G10: =IF($I10="","",IF(INDEX(Assessment!$I:$I,$I10)="","",INDEX(Assessment!$I:$I,$I10))) | H10: =IF($I10="","",IF(INDEX(Assessment!$J:$J,$I10)="","",INDEX(Assessment!$J:$J,$I10))) | I10: =IFERROR(MATCH(ROW()-4,Assessment!$L:$L,0),"")
A11: =IF($I11="","",IF(INDEX(Assessment!$A:$A,$I11)="","",INDEX(Assessment!$A:$A,$I11))) | B11: =IF($I11="","",IF(INDEX(Assessment!$B:$B,$I11)="","",INDEX(Assessment!$B:$B,$I11))) | C11: =IF($I11="","",IF(INDEX(Assessment!$E:$E,$I11)="","",INDEX(Assessment!$E:$E,$I11))) | D11: =IF($I11="","",IF(INDEX(Assessment!$C:$C,$I11)="","",INDEX(Assessment!$C:$C,$I11))) | E11: =IF($I11="","",IF(INDEX(Assessment!$D:$D,$I11)="","",INDEX(Assessment!$D:$D,$I11))) | F11: =IF($I11="","",IF(INDEX(Assessment!$H:$H,$I11)="","",INDEX(Assessment!$H:$H,$I11))) | G11: =IF($I11="","",IF(INDEX(Assessment!$I:$I,$I11)="","",INDEX(Assessment!$I:$I,$I11))) | H11: =IF($I11="","",IF(INDEX(Assessment!$J:$J,$I11)="","",INDEX(Assessment!$J:$J,$I11))) | I11: =IFERROR(MATCH(ROW()-4,Assessment!$L:$L,0),"")
A12: =IF($I12="","",IF(INDEX(Assessment!$A:$A,$I12)="","",INDEX(Assessment!$A:$A,$I12))) | B12: =IF($I12="","",IF(INDEX(Assessment!$B:$B,$I12)="","",INDEX(Assessment!$B:$B,$I12))) | C12: =IF($I12="","",IF(INDEX(Assessment!$E:$E,$I12)="","",INDEX(Assessment!$E:$E,$I12))) | D12: =IF($I12="","",IF(INDEX(Assessment!$C:$C,$I12)="","",INDEX(Assessment!$C:$C,$I12))) | E12: =IF($I12="","",IF(INDEX(Assessment!$D:$D,$I12)="","",INDEX(Assessment!$D:$D,$I12))) | F12: =IF($I12="","",IF(INDEX(Assessment!$H:$H,$I12)="","",INDEX(Assessment!$H:$H,$I12))) | G12: =IF($I12="","",IF(INDEX(Assessment!$I:$I,$I12)="","",INDEX(Assessment!$I:$I,$I12))) | H12: =IF($I12="","",IF(INDEX(Assessment!$J:$J,$I12)="","",INDEX(Assessment!$J:$J,$I12))) | I12: =IFERROR(MATCH(ROW()-4,Assessment!$L:$L,0),"")
A13: =IF($I13="","",IF(INDEX(Assessment!$A:$A,$I13)="","",INDEX(Assessment!$A:$A,$I13))) | B13: =IF($I13="","",IF(INDEX(Assessment!$B:$B,$I13)="","",INDEX(Assessment!$B:$B,$I13))) | C13: =IF($I13="","",IF(INDEX(Assessment!$E:$E,$I13)="","",INDEX(Assessment!$E:$E,$I13))) | D13: =IF($I13="","",IF(INDEX(Assessment!$C:$C,$I13)="","",INDEX(Assessment!$C:$C,$I13))) | E13: =IF($I13="","",IF(INDEX(Assessment!$D:$D,$I13)="","",INDEX(Assessment!$D:$D,$I13))) | F13: =IF($I13="","",IF(INDEX(Assessment!$H:$H,$I13)="","",INDEX(Assessment!$H:$H,$I13))) | G13: =IF($I13="","",IF(INDEX(Assessment!$I:$I,$I13)="","",INDEX(Assessment!$I:$I,$I13))) | H13: =IF($I13="","",IF(INDEX(Assessment!$J:$J,$I13)="","",INDEX(Assessment!$J:$J,$I13))) | I13: =IFERROR(MATCH(ROW()-4,Assessment!$L:$L,0),"")
A14: =IF($I14="","",IF(INDEX(Assessment!$A:$A,$I14)="","",INDEX(Assessment!$A:$A,$I14))) | B14: =IF($I14="","",IF(INDEX(Assessment!$B:$B,$I14)="","",INDEX(Assessment!$B:$B,$I14))) | C14: =IF($I14="","",IF(INDEX(Assessment!$E:$E,$I14)="","",INDEX(Assessment!$E:$E,$I14))) | D14: =IF($I14="","",IF(INDEX(Assessment!$C:$C,$I14)="","",INDEX(Assessment!$C:$C,$I14))) | E14: =IF($I14="","",IF(INDEX(Assessment!$D:$D,$I14)="","",INDEX(Assessment!$D:$D,$I14))) | F14: =IF($I14="","",IF(INDEX(Assessment!$H:$H,$I14)="","",INDEX(Assessment!$H:$H,$I14))) | G14: =IF($I14="","",IF(INDEX(Assessment!$I:$I,$I14)="","",INDEX(Assessment!$I:$I,$I14))) | H14: =IF($I14="","",IF(INDEX(Assessment!$J:$J,$I14)="","",INDEX(Assessment!$J:$J,$I14))) | I14: =IFERROR(MATCH(ROW()-4,Assessment!$L:$L,0),"")
A15: =IF($I15="","",IF(INDEX(Assessment!$A:$A,$I15)="","",INDEX(Assessment!$A:$A,$I15))) | B15: =IF($I15="","",IF(INDEX(Assessment!$B:$B,$I15)="","",INDEX(Assessment!$B:$B,$I15))) | C15: =IF($I15="","",IF(INDEX(Assessment!$E:$E,$I15)="","",INDEX(Assessment!$E:$E,$I15))) | D15: =IF($I15="","",IF(INDEX(Assessment!$C:$C,$I15)="","",INDEX(Assessment!$C:$C,$I15))) | E15: =IF($I15="","",IF(INDEX(Assessment!$D:$D,$I15)="","",INDEX(Assessment!$D:$D,$I15))) | F15: =IF($I15="","",IF(INDEX(Assessment!$H:$H,$I15)="","",INDEX(Assessment!$H:$H,$I15))) | G15: =IF($I15="","",IF(INDEX(Assessment!$I:$I,$I15)="","",INDEX(Assessment!$I:$I,$I15))) | H15: =IF($I15="","",IF(INDEX(Assessment!$J:$J,$I15)="","",INDEX(Assessment!$J:$J,$I15))) | I15: =IFERROR(MATCH(ROW()-4,Assessment!$L:$L,0),"")
A16: =IF($I16="","",IF(INDEX(Assessment!$A:$A,$I16)="","",INDEX(Assessment!$A:$A,$I16))) | B16: =IF($I16="","",IF(INDEX(Assessment!$B:$B,$I16)="","",INDEX(Assessment!$B:$B,$I16))) | C16: =IF($I16="","",IF(INDEX(Assessment!$E:$E,$I16)="","",INDEX(Assessment!$E:$E,$I16))) | D16: =IF($I16="","",IF(INDEX(Assessment!$C:$C,$I16)="","",INDEX(Assessment!$C:$C,$I16))) | E16: =IF($I16="","",IF(INDEX(Assessment!$D:$D,$I16)="","",INDEX(Assessment!$D:$D,$I16))) | F16: =IF($I16="","",IF(INDEX(Assessment!$H:$H,$I16)="","",INDEX(Assessment!$H:$H,$I16))) | G16: =IF($I16="","",IF(INDEX(Assessment!$I:$I,$I16)="","",INDEX(Assessment!$I:$I,$I16))) | H16: =IF($I16="","",IF(INDEX(Assessment!$J:$J,$I16)="","",INDEX(Assessment!$J:$J,$I16))) | I16: =IFERROR(MATCH(ROW()-4,Assessment!$L:$L,0),"")
... A66: =IF($I66="","",IF(INDEX(Assessment!$A:$A,$I66)="","",INDEX(Assessment!$A:$A,$I66))) | B66: =IF($I66="","",IF(INDEX(Assessment!$B:$B,$I66)="","",INDEX(Assessment!$B:$B,$I66))) | C66: =IF($I66="","",IF(INDEX(Assessment!$E:$E,$I66)="","",INDEX(Assessment!$E:$E,$I66))) | D66: =IF($I66="","",IF(INDEX(Assessment!$C:$C,$I66)="","",INDEX(Assessment!$C:$C,$I66))) | E66: =IF($I66="","",IF(INDEX(Assessment!$D:$D,$I66)="","",INDEX(Assessment!$D:$D,$I66))) | F66: =IF($I66="","",IF(INDEX(Assessment!$H:$H,$I66)="","",INDEX(Assessment!$H:$H,$I66))) | G66: =IF($I66="","",IF(INDEX(Assessment!$I:$I,$I66)="","",INDEX(Assessment!$I:$I,$I66))) | H66: =IF($I66="","",IF(INDEX(Assessment!$J:$J,$I66)="","",INDEX(Assessment!$J:$J,$I66))) | I66: =IFERROR(MATCH(ROW()-4,Assessment!$L:$L,0),"")

Sheet Reference
A1: MyOrg · Reference
B3: SCORING
B4: Response scale
B5: Response | C5: Points | D5: Meaning
B6: In place | C6: 2 | D6: The control operates as described and you could evidence it to a reviewer today.
B7: Partially in place | C7: 1 | D7: Some elements operate, or the control operates without evidence, or it covers only part of the use-case.
B8: Not in place | C8: 0 | D8: The control does not operate, or has not been designed.
B9: Not applicable | C9: excluded | D9: The question does not arise for this use-case. Removed from points earned and points available, so it does not depress the score.
B11: RATING
B12: Maturity bands
B13: Band | C13: Score | D13: Reading
B14: Not established | C14: below 40% | D14: Controls are largely absent. The use-case should not be relied upon in its current form.
B15: Developing | C15: 40–64% | D15: Controls exist in parts. Material gaps remain and should carry owners and dates.
B16: Established | C16: 65–84% | D16: Controls are designed and operating, with specific gaps to close.
B17: Embedded | C17: 85% and above | D17: Controls are designed, operating, and evidenced. Sustaining them is the remaining task.
B19: SERIES
B20: The thirteen advisories
B21: Reference | C21: Control area | D21: What it covers
B22: ERM-ADV-AI-001 | C22: Human in the loop | D22: Whether human oversight cited as a control can actually achieve its objective.
B23: ERM-ADV-AI-002 | C23: Intake and risk tiering | D23: Whether the use-case is registered, tiered, and owned before it is relied upon.
B24: ERM-ADV-AI-003 | C24: Data and input controls | D24: Whether what is submitted to the AI system is controlled, minimised and traceable.
B25: ERM-ADV-AI-004 | C25: Output reliability | D25: Whether the correctness of AI output is defined, evidenced and monitored.
B26: ERM-ADV-AI-005 | C26: Third-party and embedded AI | D26: Whether supplied AI capability is diligenced, contracted for, and survivable if withdrawn.
B27: ERM-ADV-AI-006 | C27: Agent identity and access | D27: Whether AI access to firm systems is attributable, least-privilege and revocable.
B28: ERM-ADV-AI-007 | C28: Autonomy and action boundaries | D28: Whether what the AI may do is defined in advance and enforced by the system.
B29: ERM-ADV-AI-008 | C29: Prompt injection and untrusted content | D29: Whether content the firm does not control can influence what the AI does.
B30: ERM-ADV-AI-009 | C30: Logging and records | D30: Whether AI-assisted activity can be reconstructed and retained as required.
B31: ERM-ADV-AI-010 | C31: Change control | D31: Whether changes to models, prompts and configuration are assessed before they take effect.
B32: ERM-ADV-AI-011 | C32: Monitoring and effectiveness | D32: Whether continued control effectiveness is evidenced rather than assumed.
... B34: ERM-ADV-AI-013 | C34: Disclosure and transparency | D34: Whether AI involvement is disclosed where required, and claims about it are substantiated.
D35: Control areas shown in dark blue apply only where the Step 2 scoping answer is Yes.
B37: Provenance and limits Questions and expectations are taken from the HTML self-assessment (ERM-ADV-AI-SA-01), which in turn derives from the minimum standards in ERM-ADV-AI-001 to 013. The maturity bands are a construction for this tool and do not map to any external maturity scale — replace them with your own framework's bands before real use. No external regulation, standard, or framework is cited anywhere in this workbook. A high score records what the owner asserted, not what a reviewer tested. This is a de-branded template. “MyOrg” is a placeholder standing in for the organisation name, and the wordmark in each sheet header is a placeholder that needs a real name or a designed mark before this is used publicly.
B42: VIEWS EXPRESSED ARE THE AUTHOR'S OWN AND DO NOT REPRESENT THOSE OF ANY EMPLOYER OR CLIENT. THIS IS A REFERENCE TEMPLATE, NOT FIRM POLICY, AND IS NOT INVESTMENT, LEGAL, OR COMPLIANCE ADVICE.
